Workbook

Sheet Raw_Tickets_Data
A1: Ticket_ID | B1: Date_Opened | C1: Team | D1: Agent_Assigned | E1: City | F1: Channel | G1: Category | H1: Priority | I1: SLA_Target_Hours | J1: Status | K1: Date_Resolved | L1: Escalated | M1: CSAT_Score | N1: Notes
A2: TCK-21324 | B2: 11/07/2026 20:33 | C2: Billing Support | D2: Rehan Qureshi | E2: Lahore | F2: EMAIL | G2: general inquiry | H2: Medium | I2: 24 | J2: resolved | K2: 11/07/2026 21:20 | L2: No | N2: Required follow-up call
A3: TCK-20385 | B3: 16/04/2026 15:15 | C3: Tier 1 Support | D3: Zara Hussain | E3: Lahore | F3: Email | G3: Technical Issue | H3: Low | I3: 48 | J3: open | L3: No | N3: Escalated to senior agent
A4: TCK-21872 | B4: 20/04/2026 10:52 | C4: Tier 1 Support | D4: Zara Hussain | E4: Karachi | F4: chat | G4: billing issue | H4: Medium | I4: 24 | J4: Resolvd | K4: 20/04/2026 18:31 | L4: No | M4: 4 | N4: Resolved on first contact
A5: TCK-20146 | B5: 11/06/2026 19:08 | C5: Tier 1 Support | D5: Zara Hussain | E5: Peshawar | F5: portal | G5: billing issue | H5: Low | I5: 48 | J5: closed | K5: 12/06/2026 22:25 | L5: No | M5: 3 | N5: Technical issue resolved remotely
A6: TCK-21894 | B6: 18/06/2026 23:02 | C6: Tier 2 Support | D6: Mahnoor Aslam | E6: Lahore | F6: Portal | G6: billing issue | H6: Low | I6: 48 | J6: Re-opened | K6: 24/06/2026 21:51 | L6: No | N6: Customer satisfied with resolution
A7: TCK-21895 | B7: 13/05/2026 12:41 | C7: Tier 2 Support | D7: Bilal Chaudhry | E7: Karachi | F7: Live Chat | G7: billing issue | H7: Medium | I7: 24 | J7: Resolvd | K7: 15/05/2026 05:27 | L7: No | N7: Repeat issue from same customer
A8: TCK-20861 | B8: 24/05/2026 03:57 | C8: Technical Support | D8: Iqra Basit | E8: Lahore | F8: phone | G8: technical issue | H8: Medium | I8: 24 | J8: resolved | K8: 25/05/2026 09:12 | L8: No | N8: Required follow-up call
A9: TCK-22644 | B9: 18/03/2026 23:31 | C9: Technical Support | D9: Iqra Basit | E9: Karachi | F9: portal | G9: general inquiry | H9: High | I9: 8 | J9: Closed | K9: 19/03/2026 03:11 | L9: No | N9: Technical issue resolved remotely
A10: TCK-23174 | B10: 08/02/2026 09:40 | C10: Tier 2 Support | D10: Bilal Chaudhry | E10: Islamabad | F10: phone | G10: technical issue | H10: Critical | I10: 4 | J10: closed | K10: 08/02/2026 12:58 | L10: No | M10: 5 | N10: Customer satisfied with resolution
A11: TCK-22892 | B11: 17/05/2026 10:11 | C11: Billing Support | D11: Sadia Anwar | E11: Faisalabad | F11: phone | G11: technical issue | H11: High | I11: 8 | J11: Resolvd | K11: 17/05/2026 16:51 | L11: No
A12: TCK-22430 | B12: 03/06/2026 17:25 | C12: Technical Support | D12: Talha Nadeem | E12: Multan | F12: portal | G12: ACCOUNT ACCESS | H12: Low | I12: 48 | J12: Escalated | L12: Yes
A13: TCK-22748 | B13: 27/02/2026 19:17 | C13: Technical Support | D13: Talha Nadeem | E13: Peshawar | F13: Chat | G13: delivery delay | H13: Low | I13: 48 | J13: Escalated | L13: Yes | N13: Repeat issue from same customer
A14: TCK-21997 | B14: 07/01/2026 17:20 | C14: Tier 1 Support | D14: Ayaan Khalid | E14: Karachi | F14: chat | G14: Delivery Delay | H14: Critical | I14: 4 | J14: resolved | K14: 07/01/2026 18:59 | L14: No
A15: TCK-21076 | B15: 10/02/2026 22:38 | C15: Billing Support | D15: Sadia Anwar | E15: Multan | F15: portal | G15: GENERAL INQUIRY | H15: Medium | I15: 24 | J15: Resolved | K15: 11/02/2026 02:05 | L15: No | M15: 4 | N15: Technical issue resolved remotely
A16: TCK-21836 | B16: 28/06/2026 15:46 | C16: Billing Support | D16: Sadia Anwar | E16: Multan | F16: EMAIL | G16: Refund Request | H16: Low | I16: 48 | J16: open | L16: No | N16: Repeat issue from same customer
A17: TCK-20694 | B17: 11/04/2026 16:39 | C17: Tier 2 Support | D17: Mahnoor Aslam | E17: Lahore | F17: Phone | G17: GENERAL INQUIRY | H17: Critical | I17: 4 | J17: resolved | K17: 11/04/2026 17:13 | L17: No | M17: 5 | N17: Resolved on first contact
A18: TCK-21727 | B18: 20/06/2026 02:24 | C18: Tier 1 Support | D18: Ayaan Khalid | E18: Multan | F18: Chat | G18: billing issue | H18: Critical | I18: 4 | J18: InProgress | L18: No | N18: Awaiting customer response
A19: TCK-22363 | B19: 09/07/2026 12:04 | C19: Billing Support | D19: Sadia Anwar | E19: Karachi | F19: Email | G19: refund request | H19: Medium | I19: 24 | J19: resolved | K19: 09/07/2026 13:07 | L19: No | N19: Customer satisfied with resolution
A20: TCK-21516 | B20: 26/03/2026 14:31 | C20: Technical Support | D20: Iqra Basit | E20: Faisalabad | F20: PHONE | G20: Delivery Delay | H20: Low | I20: 48 | J20: closed | K20: 27/03/2026 08:42 | L20: No | M20: 4 | N20: Customer requested refund
A21: TCK-21810 | B21: 11/06/2026 07:46 | C21: Tier 1 Support | D21: Zara Hussain | E21: Peshawar | F21: Web Portal | G21: Delivery Delay | H21: Medium | I21: 24 | J21: resolved | K21: 13/06/2026 09:04 | L21: No | M21: 3 | N21: Customer requested refund
A22: TCK-20701 | B22: 19/01/2026 10:18 | C22: Tier 1 Support | D22: Zara Hussain | E22: Islamabad | F22: PHONE | G22: BILLING ISSUE | H22: Low | I22: 48 | J22: closed | K22: 22/01/2026 09:44 | L22: No | N22: Repeat issue from same customer
A23: TCK-21274 | B23: 03/07/2026 16:18 | C23: Technical Support | D23: Iqra Basit | E23: Islamabad | F23: Web Portal | G23: account access | H23: Medium | I23: 24 | J23: closed | K23: 03/07/2026 23:20 | L23: No | M23: 4 | N23: Required follow-up call
A24: TCK-21771 | B24: 19/06/2026 06:46 | C24: Billing Support | D24: Sadia Anwar | E24: Karachi | F24: email | G24: Tech Issue | H24: Low | I24: 48 | J24: OPEN | L24: No | N24: Awaiting customer response
A25: TCK-20578 | B25: 10/04/2026 21:02 | C25: Billing Support | D25: Rehan Qureshi | E25: Rawalpindi | F25: chat | G25: account access | H25: Medium | I25: 24 | J25: In Progress | L25: No | N25: Awaiting customer response
A26: TCK-21957 | B26: 13/06/2026 10:28 | C26: Tier 1 Support | D26: Ayaan Khalid | E26: Karachi | F26: portal | G26: Delivery Delay | H26: High | I26: 8 | J26: Resolved | K26: 13/06/2026 13:24 | L26: No | N26: Customer satisfied with resolution
A27: TCK-23150 | B27: 29/08/2026 16:39 | C27: Tier 1 Support | D27: Zara Hussain | E27: Rawalpindi | F27: EMAIL | G27: refund request | H27: Medium | I27: 24 | J27: in progress | L27: No | N27: Customer requested refund
A28: TCK-21907 | B28: 14/08/2026 20:10 | C28: Technical Support | D28: Talha Nadeem | E28: Islamabad | F28: Email | G28: Refund Request | H28: Medium | I28: 24 | J28: Closed | K28: 15/08/2026 17:20 | L28: No | M28: 2
A29: TCK-20794 | B29: 12/05/2026 20:17 | C29: Tier 2 Support | D29: Mahnoor Aslam | E29: Faisalabad | F29: Web Portal | G29: general inquiry | H29: Medium | I29: 24 | J29: open | L29: No | N29: Repeat issue from same customer
A30: TCK-20075 | B30: 30/08/2026 15:37 | C30: Tier 2 Support | D30: Bilal Chaudhry | E30: Multan | F30: Chat | G30: Delivery Delay | H30: Medium | I30: 24 | J30: Resolvd | K30: 31/08/2026 09:53 | L30: No | M30: 2
A31: TCK-23081 | B31: 03/08/2026 04:49 | C31: Tier 1 Support | D31: Ayaan Khalid | E31: Rawalpindi | F31: portal | G31: account access | H31: Low | I31: 48 | J31: resolved | K31: 03/08/2026 07:37 | L31: Yes | M31: 2 | N31: Customer requested refund
A32: TCK-21231 | B32: 24/08/2026 22:45 | C32: Tier 2 Support | D32: Mahnoor Aslam | E32: Lahore | F32: Chat | G32: technical issue | H32: Low | I32: 48 | J32: resolved | K32: 27/08/2026 06:00 | L32: No | M32: 3 | N32: Repeat issue from same customer
A33: TCK-22702 | B33: 09/07/2026 07:18 | C33: Billing Support | D33: Sadia Anwar | E33: Peshawar | F33: portal | G33: GENERAL INQUIRY | H33: Medium | I33: 24 | J33: Closed | K33: 09/07/2026 19:03 | L33: No | N33: Repeat issue from same customer
A34: TCK-22931 | B34: 19/04/2026 12:38 | C34: Tier 1 Support | D34: Zara Hussain | E34: Faisalabad | F34: portal | G34: Refund Request | H34: Critical | I34: 4 | J34: Escalated | L34: Yes | N34: Customer requested refund
A35: TCK-21721 | B35: 07/08/2026 16:42 | C35: Billing Support | D35: Sadia Anwar | E35: Faisalabad | F35: chat | G35: Billing Issue | H35: Low | I35: 48 | J35: Closed | K35: 09/08/2026 09:55 | L35: No | M35: 2 | N35: Technical issue resolved remotely
A36: TCK-20492 | B36: 04/02/2026 03:25 | C36: Billing Support | D36: Rehan Qureshi | E36: Lahore | F36: phone | G36: Account Access | H36: Medium | I36: 24 | J36: Closed | K36: 04/02/2026 05:35 | L36: No | M36: 1 | N36: Customer satisfied with resolution
A37: TCK-21757 | B37: 21/01/2026 18:20 | C37: Tier 2 Support | D37: Bilal Chaudhry | E37: Lahore | F37: portal | G37: refund request | H37: Medium | I37: 24 | J37: CLOSED | K37: 21/01/2026 21:03 | L37: No | M37: 5
A38: TCK-20017 | B38: 06/02/2026 09:53 | C38: Billing Support | D38: Rehan Qureshi | E38: Peshawar | F38: EMAIL | G38: Refund Request | H38: Medium | I38: 24 | J38: reopened | L38: No
A39: TCK-22401 | B39: 06/06/2026 01:56 | C39: Billing Support | D39: Sadia Anwar | E39: Faisalabad | F39: Phone | G39: general inquiry | H39: High | I39: 8 | J39: CLOSED | K39: 06/06/2026 07:22 | L39: No | M39: 1 | N39: Escalated to senior agent
A40: TCK-21540 | B40: 22/08/2026 15:21 | C40: Technical Support | D40: Iqra Basit | E40: Multan | F40: portal | G40: Technical Issue | H40: Medium | I40: 24 | J40: Closed | K40: 23/08/2026 11:34 | L40: No | M40: 5 | N40: Required follow-up call
...

Sheet PT_ByTeam
A3: Row Labels | B3: Count of Ticket_ID | C3: Average of Resolution_Hours
A4: Billing Support | B4: 787 | C4: 20.886456
A5: Technical Support | B5: 802 | C5: 21.391651
A6: Tier 1 Support | B6: 799 | C6: 21.537091
A7: Tier 2 Support | B7: 812 | C7: 20.598576
A8: Grand Total | B8: 3200 | C8: 21.097292

Sheet PT_ByAgent
A3: Count of Ticket_ID | B3: Column Labels
B4: Closed | C4: Closed Total | D4: Escalated | E4: Escalated Total | F4: In Progress | G4: In Progress Total | H4: Open | I4: Open Total | J4: Re-Opened | K4: Re-Opened Total | L4: Resolved | N4: Resolved Total | O4: Grand Total
A5: Row Labels | B5: N/A | D5: N/A | F5: N/A | H5: N/A | J5: N/A | L5: No | M5: Yes
A6: Ayaan Khalid | B6: 93 | C6: 93 | D6: 54 | E6: 54 | F6: 39 | G6: 39 | H6: 33 | I6: 33 | J6: 12 | K6: 12 | L6: 42 | M6: 110 | N6: 152 | O6: 383
A7: Bilal Chaudhry | B7: 93 | C7: 93 | D7: 42 | E7: 42 | F7: 40 | G7: 40 | H7: 27 | I7: 27 | J7: 27 | K7: 27 | L7: 43 | M7: 138 | N7: 181 | O7: 410
A8: Iqra Basit | B8: 105 | C8: 105 | D8: 44 | E8: 44 | F8: 57 | G8: 57 | H8: 30 | I8: 30 | J8: 22 | K8: 22 | L8: 41 | M8: 116 | N8: 157 | O8: 415
A9: Mahnoor Aslam | B9: 101 | C9: 101 | D9: 50 | E9: 50 | F9: 37 | G9: 37 | H9: 42 | I9: 42 | J9: 12 | K9: 12 | L9: 36 | M9: 124 | N9: 160 | O9: 402
A10: Rehan Qureshi | B10: 89 | C10: 89 | D10: 36 | E10: 36 | F10: 40 | G10: 40 | H10: 35 | I10: 35 | J10: 15 | K10: 15 | L10: 37 | M10: 127 | N10: 164 | O10: 379
A11: Sadia Anwar | B11: 102 | C11: 102 | D11: 45 | E11: 45 | F11: 40 | G11: 40 | H11: 42 | I11: 42 | J11: 22 | K11: 22 | L11: 47 | M11: 110 | N11: 157 | O11: 408
A12: Talha Nadeem | B12: 101 | C12: 101 | D12: 43 | E12: 43 | F12: 44 | G12: 44 | H12: 40 | I12: 40 | J12: 20 | K12: 20 | L12: 36 | M12: 103 | N12: 139 | O12: 387
A13: Zara Hussain | B13: 100 | C13: 100 | D13: 42 | E13: 42 | F13: 54 | G13: 54 | H13: 27 | I13: 27 | J13: 29 | K13: 29 | L13: 55 | M13: 109 | N13: 164 | O13: 416
A14: Grand Total | B14: 784 | C14: 784 | D14: 356 | E14: 356 | F14: 351 | G14: 351 | H14: 276 | I14: 276 | J14: 159 | K14: 159 | L14: 337 | M14: 937 | N14: 1274 | O14: 3200

Sheet PT_ByCity
A3: Row Labels | B3: Count of Ticket_ID
A4: Faisalabad | B4: 422
A5: Islamabad | B5: 466
A6: Karachi | B6: 460
A7: Lahore | B7: 462
A8: Multan | B8: 444
A9: Not Specified | B9: 4
A10: Peshawar | B10: 492
A11: Rawalpindi | B11: 450
A12: Grand Total | B12: 3200

Sheet PT_ByChannel
A3: Row Labels | B3: Count of Ticket_ID
A4: Chat | B4: 798
A5: Email | B5: 815
A6: Phone | B6: 754
A7: Portal | B7: 833
A8: Grand Total | B8: 3200

Sheet PT_ByCategory
A3: Row Labels | B3: Count of Ticket_ID
A4: Account Access | B4: 539
A5: Billing Issue | B5: 508
A6: Delivery Delay | B6: 515
A7: General Inquiry | B7: 542
A8: Refund Request | B8: 563
A9: Technical Issue | B9: 533
A10: Grand Total | B10: 3200

Sheet PT_ByPriority
A3: Row Labels | B3: Count of Ticket_ID | C3: Average of Resolution_Hours
A4: Critical | B4: 297 | C4: 3.4339226
A5: High | B5: 756 | C5: 6.4549595
A6: Low | B6: 991 | C6: 40.005965
A7: Medium | B7: 1156 | C7: 19.44217
A8: Grand Total | B8: 3200 | C8: 21.097292

Sheet PT_CategoryPriority
A3: Count of Ticket_ID | B3: Column Labels
A4: Row Labels | B4: N/A | C4: No | D4: Yes | E4: Grand Total
A5: Account Access | B5: 350 | C5: 54 | D5: 135 | E5: 539
A6: Critical | B6: 25 | C6: 4 | D6: 10 | E6: 39
A7: High | B7: 86 | C7: 18 | D7: 33 | E7: 137
A8: Low | B8: 114 | C8: 12 | D8: 42 | E8: 168
A9: Medium | B9: 125 | C9: 20 | D9: 50 | E9: 195
A10: Billing Issue | B10: 303 | C10: 57 | D10: 148 | E10: 508
A11: Critical | B11: 30 | C11: 8 | D11: 20 | E11: 58
A12: High | B12: 74 | C12: 10 | D12: 34 | E12: 118
A13: Low | B13: 104 | C13: 16 | D13: 38 | E13: 158
A14: Medium | B14: 95 | C14: 23 | D14: 56 | E14: 174
A15: Delivery Delay | B15: 328 | C15: 41 | D15: 146 | E15: 515
A16: Critical | B16: 28 | C16: 5 | D16: 13 | E16: 46
... A35: Grand Total | B35: 1926 | C35: 337 | D35: 937 | E35: 3200

Sheet Working_Data
A1: Ticket_ID | B1: Date_Opened | C1: Team | D1: Agent_Assigned | E1: City | F1: Channel | G1: Category | H1: Priority | I1: SLA_Target_Hours | J1: Status | K1: Date_Resolved | L1: Escalated | M1: CSAT_Score | N1: Notes | O1: Resolution_Hours | P1: Met_SLA
A2: TCK-21324 | B2: 46214.856 | C2: Billing Support | D2: Rehan Qureshi | E2: Lahore | F2: Email | G2: General Inquiry | H2: Medium | I2: 24 | J2: Resolved | K2: 46214.889 | L2: No | N2: Required Follow-Up Call | O2: =IF(K2="","",IF(K2="Missing Resolve Date","",(K2-B2)*24)) -> 0.78333333 | P2: =IF(J2="Resolved",IF(O2<=I2,"Yes","No"),"N/A") -> Yes
A3: TCK-20385 | B3: 46128.635 | C3: Tier 1 Support | D3: Zara Hussain | E3: Lahore | F3: Email | G3: Technical Issue | H3: Low | I3: 48 | J3: Open | K3: Missing Resolve Date | L3: No | N3: Escalated To Senior Agent | O3: =IF(K3="","",IF(K3="Missing Resolve Date","",(K3-B3)*24)) | P3: =IF(J3="Resolved",IF(O3<=I3,"Yes","No"),"N/A") -> N/A
A4: TCK-21872 | B4: 46132.453 | C4: Tier 1 Support | D4: Zara Hussain | E4: Karachi | F4: Chat | G4: Billing Issue | H4: Medium | I4: 24 | J4: Resolved | K4: 46132.772 | L4: No | M4: 4 | N4: Resolved On First Contact | O4: =IF(K4="","",IF(K4="Missing Resolve Date","",(K4-B4)*24)) -> 7.65 | P4: =IF(J4="Resolved",IF(O4<=I4,"Yes","No"),"N/A") -> Yes
A5: TCK-20146 | B5: 46184.797 | C5: Tier 1 Support | D5: Zara Hussain | E5: Peshawar | F5: Portal | G5: Billing Issue | H5: Low | I5: 48 | J5: Closed | K5: 46185.934 | L5: No | M5: 3 | N5: Technical Issue Resolved Remotely | O5: =IF(K5="","",IF(K5="Missing Resolve Date","",(K5-B5)*24)) -> 27.283333 | P5: =IF(J5="Resolved",IF(O5<=I5,"Yes","No"),"N/A") -> N/A
A6: TCK-21894 | B6: 46191.96 | C6: Tier 2 Support | D6: Mahnoor Aslam | E6: Lahore | F6: Portal | G6: Billing Issue | H6: Low | I6: 48 | J6: Re-Opened | K6: 46197.91 | L6: No | N6: Customer Satisfied With Resolution | O6: =IF(K6="","",IF(K6="Missing Resolve Date","",(K6-B6)*24)) -> 142.81667 | P6: =IF(J6="Resolved",IF(O6<=I6,"Yes","No"),"N/A") -> N/A
A7: TCK-21895 | B7: 46155.528 | C7: Tier 2 Support | D7: Bilal Chaudhry | E7: Karachi | F7: Chat | G7: Billing Issue | H7: Medium | I7: 24 | J7: Resolved | K7: 46157.227 | L7: No | N7: Repeat Issue From Same Customer | O7: =IF(K7="","",IF(K7="Missing Resolve Date","",(K7-B7)*24)) -> 40.766667 | P7: =IF(J7="Resolved",IF(O7<=I7,"Yes","No"),"N/A") -> No
A8: TCK-20861 | B8: 46166.165 | C8: Technical Support | D8: Iqra Basit | E8: Lahore | F8: Phone | G8: Technical Issue | H8: Medium | I8: 24 | J8: Resolved | K8: 46167.383 | L8: No | N8: Required Follow-Up Call | O8: =IF(K8="","",IF(K8="Missing Resolve Date","",(K8-B8)*24)) -> 29.25 | P8: =IF(J8="Resolved",IF(O8<=I8,"Yes","No"),"N/A") -> No
A9: TCK-22644 | B9: 46099.98 | C9: Technical Support | D9: Iqra Basit | E9: Karachi | F9: Portal | G9: General Inquiry | H9: High | I9: 8 | J9: Closed | K9: 46100.133 | L9: No | N9: Technical Issue Resolved Remotely | O9: =IF(K9="","",IF(K9="Missing Resolve Date","",(K9-B9)*24)) -> 3.6666667 | P9: =IF(J9="Resolved",IF(O9<=I9,"Yes","No"),"N/A") -> N/A
A10: TCK-23174 | B10: 46061.403 | C10: Tier 2 Support | D10: Bilal Chaudhry | E10: Islamabad | F10: Phone | G10: Technical Issue | H10: Critical | I10: 4 | J10: Closed | K10: 46061.54 | L10: No | M10: 5 | N10: Customer Satisfied With Resolution | O10: =IF(K10="","",IF(K10="Missing Resolve Date","",(K10-B10)*24)) -> 3.3 | P10: =IF(J10="Resolved",IF(O10<=I10,"Yes","No"),"N/A") -> N/A
A11: TCK-22892 | B11: 46159.424 | C11: Billing Support | D11: Sadia Anwar | E11: Faisalabad | F11: Phone | G11: Technical Issue | H11: High | I11: 8 | J11: Resolved | K11: 46159.702 | L11: No | N11: Not Specified | O11: =IF(K11="","",IF(K11="Missing Resolve Date","",(K11-B11)*24)) -> 6.6666667 | P11: =IF(J11="Resolved",IF(O11<=I11,"Yes","No"),"N/A") -> Yes
A12: TCK-22430 | B12: 46176.726 | C12: Technical Support | D12: Talha Nadeem | E12: Multan | F12: Portal | G12: Account Access | H12: Low | I12: 48 | J12: Escalated | K12: Missing Resolve Date | L12: Yes | N12: Not Specified | O12: =IF(K12="","",IF(K12="Missing Resolve Date","",(K12-B12)*24)) | P12: =IF(J12="Resolved",IF(O12<=I12,"Yes","No"),"N/A") -> N/A
A13: TCK-22748 | B13: 46080.803 | C13: Technical Support | D13: Talha Nadeem | E13: Peshawar | F13: Chat | G13: Delivery Delay | H13: Low | I13: 48 | J13: Escalated | K13: Missing Resolve Date | L13: Yes | N13: Repeat Issue From Same Customer | O13: =IF(K13="","",IF(K13="Missing Resolve Date","",(K13-B13)*24)) | P13: =IF(J13="Resolved",IF(O13<=I13,"Yes","No"),"N/A") -> N/A
A14: TCK-21997 | B14: 46029.722 | C14: Tier 1 Support | D14: Ayaan Khalid | E14: Karachi | F14: Chat | G14: Delivery Delay | H14: Critical | I14: 4 | J14: Resolved | K14: 46029.791 | L14: No | N14: Not Specified | O14: =IF(K14="","",IF(K14="Missing Resolve Date","",(K14-B14)*24)) -> 1.65 | P14: =IF(J14="Resolved",IF(O14<=I14,"Yes","No"),"N/A") -> Yes
A15: TCK-21076 | B15: 46063.943 | C15: Billing Support | D15: Sadia Anwar | E15: Multan | F15: Portal | G15: General Inquiry | H15: Medium | I15: 24 | J15: Resolved | K15: 46064.087 | L15: No | M15: 4 | N15: Technical Issue Resolved Remotely | O15: =IF(K15="","",IF(K15="Missing Resolve Date","",(K15-B15)*24)) -> 3.45 | P15: =IF(J15="Resolved",IF(O15<=I15,"Yes","No"),"N/A") -> Yes
A16: TCK-21836 | B16: 46201.657 | C16: Billing Support | D16: Sadia Anwar | E16: Multan | F16: Email | G16: Refund Request | H16: Low | I16: 48 | J16: Open | K16: Missing Resolve Date | L16: No | N16: Repeat Issue From Same Customer | O16: =IF(K16="","",IF(K16="Missing Resolve Date","",(K16-B16)*24)) | P16: =IF(J16="Resolved",IF(O16<=I16,"Yes","No"),"N/A") -> N/A
A17: TCK-20694 | B17: 46123.694 | C17: Tier 2 Support | D17: Mahnoor Aslam | E17: Lahore | F17: Phone | G17: General Inquiry | H17: Critical | I17: 4 | J17: Resolved | K17: 46123.717 | L17: No | M17: 5 | N17: Resolved On First Contact | O17: =IF(K17="","",IF(K17="Missing Resolve Date","",(K17-B17)*24)) -> 0.56666667 | P17: =IF(J17="Resolved",IF(O17<=I17,"Yes","No"),"N/A") -> Yes
A18: TCK-21727 | B18: 46193.1 | C18: Tier 1 Support | D18: Ayaan Khalid | E18: Multan | F18: Chat | G18: Billing Issue | H18: Critical | I18: 4 | J18: In Progress | K18: Missing Resolve Date | L18: No | N18: Awaiting Customer Response | O18: =IF(K18="","",IF(K18="Missing Resolve Date","",(K18-B18)*24)) | P18: =IF(J18="Resolved",IF(O18<=I18,"Yes","No"),"N/A") -> N/A
A19: TCK-22363 | B19: 46212.503 | C19: Billing Support | D19: Sadia Anwar | E19: Karachi | F19: Email | G19: Refund Request | H19: Medium | I19: 24 | J19: Resolved | K19: 46212.547 | L19: No | N19: Customer Satisfied With Resolution | O19: =IF(K19="","",IF(K19="Missing Resolve Date","",(K19-B19)*24)) -> 1.05 | P19: =IF(J19="Resolved",IF(O19<=I19,"Yes","No"),"N/A") -> Yes
A20: TCK-21516 | B20: 46107.605 | C20: Technical Support | D20: Iqra Basit | E20: Faisalabad | F20: Phone | G20: Delivery Delay | H20: Low | I20: 48 | J20: Closed | K20: 46108.363 | L20: No | M20: 4 | N20: Customer Requested Refund | O20: =IF(K20="","",IF(K20="Missing Resolve Date","",(K20-B20)*24)) -> 18.183333 | P20: =IF(J20="Resolved",IF(O20<=I20,"Yes","No"),"N/A") -> N/A
A21: TCK-21810 | B21: 46184.324 | C21: Tier 1 Support | D21: Zara Hussain | E21: Peshawar | F21: Portal | G21: Delivery Delay | H21: Medium | I21: 24 | J21: Resolved | K21: 46186.378 | L21: No | M21: 3 | N21: Customer Requested Refund | O21: =IF(K21="","",IF(K21="Missing Resolve Date","",(K21-B21)*24)) -> 49.3 | P21: =IF(J21="Resolved",IF(O21<=I21,"Yes","No"),"N/A") -> No
A22: TCK-20701 | B22: 46041.429 | C22: Tier 1 Support | D22: Zara Hussain | E22: Islamabad | F22: Phone | G22: Billing Issue | H22: Low | I22: 48 | J22: Closed | K22: 46044.406 | L22: No | N22: Repeat Issue From Same Customer | O22: =IF(K22="","",IF(K22="Missing Resolve Date","",(K22-B22)*24)) -> 71.433333 | P22: =IF(J22="Resolved",IF(O22<=I22,"Yes","No"),"N/A") -> N/A
A23: TCK-21274 | B23: 46206.679 | C23: Technical Support | D23: Iqra Basit | E23: Islamabad | F23: Portal | G23: Account Access | H23: Medium | I23: 24 | J23: Closed | K23: 46206.972 | L23: No | M23: 4 | N23: Required Follow-Up Call | O23: =IF(K23="","",IF(K23="Missing Resolve Date","",(K23-B23)*24)) -> 7.0333333 | P23: =IF(J23="Resolved",IF(O23<=I23,"Yes","No"),"N/A") -> N/A
A24: TCK-21771 | B24: 46192.282 | C24: Billing Support | D24: Sadia Anwar | E24: Karachi | F24: Email | G24: Technical Issue | H24: Low | I24: 48 | J24: Open | K24: Missing Resolve Date | L24: No | N24: Awaiting Customer Response | O24: =IF(K24="","",IF(K24="Missing Resolve Date","",(K24-B24)*24)) | P24: =IF(J24="Resolved",IF(O24<=I24,"Yes","No"),"N/A") -> N/A
A25: TCK-20578 | B25: 46122.876 | C25: Billing Support | D25: Rehan Qureshi | E25: Rawalpindi | F25: Chat | G25: Account Access | H25: Medium | I25: 24 | J25: In Progress | K25: Missing Resolve Date | L25: No | N25: Awaiting Customer Response | O25: =IF(K25="","",IF(K25="Missing Resolve Date","",(K25-B25)*24)) | P25: =IF(J25="Resolved",IF(O25<=I25,"Yes","No"),"N/A") -> N/A
A26: TCK-21957 | B26: 46186.436 | C26: Tier 1 Support | D26: Ayaan Khalid | E26: Karachi | F26: Portal | G26: Delivery Delay | H26: High | I26: 8 | J26: Resolved | K26: 46186.558 | L26: No | N26: Customer Satisfied With Resolution | O26: =IF(K26="","",IF(K26="Missing Resolve Date","",(K26-B26)*24)) -> 2.9333333 | P26: =IF(J26="Resolved",IF(O26<=I26,"Yes","No"),"N/A") -> Yes
A27: TCK-23150 | B27: 46263.694 | C27: Tier 1 Support | D27: Zara Hussain | E27: Rawalpindi | F27: Email | G27: Refund Request | H27: Medium | I27: 24 | J27: In Progress | K27: Missing Resolve Date | L27: No | N27: Customer Requested Refund | O27: =IF(K27="","",IF(K27="Missing Resolve Date","",(K27-B27)*24)) | P27: =IF(J27="Resolved",IF(O27<=I27,"Yes","No"),"N/A") -> N/A
A28: TCK-21907 | B28: 46248.84 | C28: Technical Support | D28: Talha Nadeem | E28: Islamabad | F28: Email | G28: Refund Request | H28: Medium | I28: 24 | J28: Closed | K28: 46249.722 | L28: No | M28: 2 | N28: Not Specified | O28: =IF(K28="","",IF(K28="Missing Resolve Date","",(K28-B28)*24)) -> 21.166667 | P28: =IF(J28="Resolved",IF(O28<=I28,"Yes","No"),"N/A") -> N/A
A29: TCK-20794 | B29: 46154.845 | C29: Tier 2 Support | D29: Mahnoor Aslam | E29: Faisalabad | F29: Portal | G29: General Inquiry | H29: Medium | I29: 24 | J29: Open | K29: Missing Resolve Date | L29: No | N29: Repeat Issue From Same Customer | O29: =IF(K29="","",IF(K29="Missing Resolve Date","",(K29-B29)*24)) | P29: =IF(J29="Resolved",IF(O29<=I29,"Yes","No"),"N/A") -> N/A
A30: TCK-20075 | B30: 46264.651 | C30: Tier 2 Support | D30: Bilal Chaudhry | E30: Multan | F30: Chat | G30: Delivery Delay | H30: Medium | I30: 24 | J30: Resolved | K30: 46265.412 | L30: No | M30: 2 | N30: Not Specified | O30: =IF(K30="","",IF(K30="Missing Resolve Date","",(K30-B30)*24)) -> 18.266667 | P30: =IF(J30="Resolved",IF(O30<=I30,"Yes","No"),"N/A") -> Yes
A31: TCK-23081 | B31: 46237.201 | C31: Tier 1 Support | D31: Ayaan Khalid | E31: Rawalpindi | F31: Portal | G31: Account Access | H31: Low | I31: 48 | J31: Resolved | K31: 46237.317 | L31: Yes | M31: 2 | N31: Customer Requested Refund | O31: =IF(K31="","",IF(K31="Missing Resolve Date","",(K31-B31)*24)) -> 2.8 | P31: =IF(J31="Resolved",IF(O31<=I31,"Yes","No"),"N/A") -> Yes
A32: TCK-21231 | B32: 46258.948 | C32: Tier 2 Support | D32: Mahnoor Aslam | E32: Lahore | F32: Chat | G32: Technical Issue | H32: Low | I32: 48 | J32: Resolved | K32: 46261.25 | L32: No | M32: 3 | N32: Repeat Issue From Same Customer | O32: =IF(K32="","",IF(K32="Missing Resolve Date","",(K32-B32)*24)) -> 55.25 | P32: =IF(J32="Resolved",IF(O32<=I32,"Yes","No"),"N/A") -> No
A33: TCK-22702 | B33: 46212.304 | C33: Billing Support | D33: Sadia Anwar | E33: Peshawar | F33: Portal | G33: General Inquiry | H33: Medium | I33: 24 | J33: Closed | K33: 46212.794 | L33: No | N33: Repeat Issue From Same Customer | O33: =IF(K33="","",IF(K33="Missing Resolve Date","",(K33-B33)*24)) -> 11.75 | P33: =IF(J33="Resolved",IF(O33<=I33,"Yes","No"),"N/A") -> N/A
A34: TCK-22931 | B34: 46131.526 | C34: Tier 1 Support | D34: Zara Hussain | E34: Faisalabad | F34: Portal | G34: Refund Request | H34: Critical | I34: 4 | J34: Escalated | K34: Missing Resolve Date | L34: Yes | N34: Customer Requested Refund | O34: =IF(K34="","",IF(K34="Missing Resolve Date","",(K34-B34)*24)) | P34: =IF(J34="Resolved",IF(O34<=I34,"Yes","No"),"N/A") -> N/A
A35: TCK-21721 | B35: 46241.696 | C35: Billing Support | D35: Sadia Anwar | E35: Faisalabad | F35: Chat | G35: Billing Issue | H35: Low | I35: 48 | J35: Closed | K35: 46243.413 | L35: No | M35: 2 | N35: Technical Issue Resolved Remotely | O35: =IF(K35="","",IF(K35="Missing Resolve Date","",(K35-B35)*24)) -> 41.216667 | P35: =IF(J35="Resolved",IF(O35<=I35,"Yes","No"),"N/A") -> N/A
A36: TCK-20492 | B36: 46057.142 | C36: Billing Support | D36: Rehan Qureshi | E36: Lahore | F36: Phone | G36: Account Access | H36: Medium | I36: 24 | J36: Closed | K36: 46057.233 | L36: No | M36: 1 | N36: Customer Satisfied With Resolution | O36: =IF(K36="","",IF(K36="Missing Resolve Date","",(K36-B36)*24)) -> 2.1666667 | P36: =IF(J36="Resolved",IF(O36<=I36,"Yes","No"),"N/A") -> N/A
A37: TCK-21757 | B37: 46043.764 | C37: Tier 2 Support | D37: Bilal Chaudhry | E37: Lahore | F37: Portal | G37: Refund Request | H37: Medium | I37: 24 | J37: Closed | K37: 46043.877 | L37: No | M37: 5 | N37: Not Specified | O37: =IF(K37="","",IF(K37="Missing Resolve Date","",(K37-B37)*24)) -> 2.7166667 | P37: =IF(J37="Resolved",IF(O37<=I37,"Yes","No"),"N/A") -> N/A
A38: TCK-20017 | B38: 46059.412 | C38: Billing Support | D38: Rehan Qureshi | E38: Peshawar | F38: Email | G38: Refund Request | H38: Medium | I38: 24 | J38: Re-Opened | K38: Missing Resolve Date | L38: No | N38: Not Specified | O38: =IF(K38="","",IF(K38="Missing Resolve Date","",(K38-B38)*24)) | P38: =IF(J38="Resolved",IF(O38<=I38,"Yes","No"),"N/A") -> N/A
A39: TCK-22401 | B39: 46179.081 | C39: Billing Support | D39: Sadia Anwar | E39: Faisalabad | F39: Phone | G39: General Inquiry | H39: High | I39: 8 | J39: Closed | K39: 46179.307 | L39: No | M39: 1 | N39: Escalated To Senior Agent | O39: =IF(K39="","",IF(K39="Missing Resolve Date","",(K39-B39)*24)) -> 5.4333333 | P39: =IF(J39="Resolved",IF(O39<=I39,"Yes","No"),"N/A") -> N/A
A40: TCK-21540 | B40: 46256.64 | C40: Technical Support | D40: Iqra Basit | E40: Multan | F40: Portal | G40: Technical Issue | H40: Medium | I40: 24 | J40: Closed | K40: 46257.482 | L40: No | M40: 5 | N40: Required Follow-Up Call | O40: =IF(K40="","",IF(K40="Missing Resolve Date","",(K40-B40)*24)) -> 20.216667 | P40: =IF(J40="Resolved",IF(O40<=I40,"Yes","No"),"N/A") -> N/A
...

Sheet Analysis_Notes
A1: DRILL-DOWN ANALYSIS
A2: Zara Hussain has the lowest SLA compliance rate among all agents at 66.5%, notably below the team average of approximately 74%, despite handling a Resolved ticket volume (164) that is in line with most other agents.
A3: Since her ticket volume is not unusually high compared to peers like Bilal Chaudhry (181 resolved, 76.2% compliance) or Rehan Qureshi (164 resolved, 77.4% compliance - an identical volume to Zara but 11 percentage points higher compliance), volume alone does not explain the gap.
A4: Zara Hussain also has the highest Escalated ticket count among all agents (42) and the highest Re-Opened count (29), suggesting a pattern where issues are either being passed upward more frequently or not being fully resolved on the first attempt - both of which could be consuming time that pushes other tickets past their SLA window.
A5: Recommend reviewing Zara Hussain's ticket assignments to check whether she is being routed a higher proportion of Critical or High priority tickets (which carry tighter SLA windows), and pairing her with a senior agent for a short coaching period focused on first-contact resolution to reduce the Re-Opened rate.
A7: Ad Hoc Analysis
A8: Question: Which Category and Priority combination has the best SLA compliance rate, with at least 100 total tickets?
A9: Answer: Delivery Delay + High Priority has the best SLA compliance rate among qualifying combinations at 84.3% (118 tickets).
A11: KEY FINDINGS
A12: 1. Overall SLA compliance stands at approximately 74%, with clear variation by priority level - Critical and High priority tickets are resolved well within their SLA windows, while Low priority tickets, though slower in absolute hours, still comfortably meet their more lenient 48-hour target.
A13: 2. Agent Zara Hussain has the lowest SLA compliance rate (66.5%) among all agents, closely followed by Sadia Anwar (70.1%) - both notably below the team average, driven partly by elevated Escalation and Re-Opened ticket counts.
A14: 3. Delivery Delay tickets at High priority achieve the strongest SLA compliance among high-volume category combinations (84.3%), while Technical Issue tickets at Medium priority underperform (66.3%) despite being the largest single combination in the dataset.
... A27: Review Zara Hussain's ticket assignment mix and escalation patterns in more detail. Confirm the ticketing system's data entry process is updated to prevent future "Resolved without timestamp" errors.

Sheet Operational_Tracker
A1: Date | B1: Tickets Opened | C1: Tickets Resolved | D1: SLA Compliance % | E1: Backlog
A2: 46023 | B2: =COUNTIFS(Working_Data!$B:$B,">="&A2,Working_Data!$B:$B,"<"&(A2+1)) -> 5 | C2: =COUNTIFS(Working_Data!$K:$K,">="&A2,Working_Data!$K:$K,"<"&(A2+1),Working_Data!$J:$J,"Resolved") -> 1 | D2: =IFERROR(SUMPRODUCT((Working_Data!$K:$K>=A2)*(Working_Data!$K:$K<(A2+1))*(Working_Data!$J:$J="Resolved")*(Working_Data!$O:$O<=Working_Data!$I:$I))/C2,0) -> 1 | E2: =COUNTIFS(Working_Data!$J:$J,"Open")+COUNTIFS(Working_Data!$J:$J,"In Progress") -> 627
A3: 46024 | B3: =COUNTIFS(Working_Data!$B:$B,">="&A3,Working_Data!$B:$B,"<"&(A3+1)) -> 15 | C3: =COUNTIFS(Working_Data!$K:$K,">="&A3,Working_Data!$K:$K,"<"&(A3+1),Working_Data!$J:$J,"Resolved") -> 3 | D3: =IFERROR(SUMPRODUCT((Working_Data!$K:$K>=A3)*(Working_Data!$K:$K<(A3+1))*(Working_Data!$J:$J="Resolved")*(Working_Data!$O:$O<=Working_Data!$I:$I))/C3,0) -> 1 | E3: =COUNTIFS(Working_Data!$J:$J,"Open")+COUNTIFS(Working_Data!$J:$J,"In Progress") -> 627
A4: 46025 | B4: =COUNTIFS(Working_Data!$B:$B,">="&A4,Working_Data!$B:$B,"<"&(A4+1)) -> 11 | C4: =COUNTIFS(Working_Data!$K:$K,">="&A4,Working_Data!$K:$K,"<"&(A4+1),Working_Data!$J:$J,"Resolved") -> 4 | D4: =IFERROR(SUMPRODUCT((Working_Data!$K:$K>=A4)*(Working_Data!$K:$K<(A4+1))*(Working_Data!$J:$J="Resolved")*(Working_Data!$O:$O<=Working_Data!$I:$I))/C4,0) -> 1 | E4: =COUNTIFS(Working_Data!$J:$J,"Open")+COUNTIFS(Working_Data!$J:$J,"In Progress") -> 627
A5: 46026 | B5: =COUNTIFS(Working_Data!$B:$B,">="&A5,Working_Data!$B:$B,"<"&(A5+1)) -> 12 | C5: =COUNTIFS(Working_Data!$K:$K,">="&A5,Working_Data!$K:$K,"<"&(A5+1),Working_Data!$J:$J,"Resolved") -> 4 | D5: =IFERROR(SUMPRODUCT((Working_Data!$K:$K>=A5)*(Working_Data!$K:$K<(A5+1))*(Working_Data!$J:$J="Resolved")*(Working_Data!$O:$O<=Working_Data!$I:$I))/C5,0) -> 1 | E5: =COUNTIFS(Working_Data!$J:$J,"Open")+COUNTIFS(Working_Data!$J:$J,"In Progress") -> 627
A6: 46027 | B6: =COUNTIFS(Working_Data!$B:$B,">="&A6,Working_Data!$B:$B,"<"&(A6+1)) -> 15 | C6: =COUNTIFS(Working_Data!$K:$K,">="&A6,Working_Data!$K:$K,"<"&(A6+1),Working_Data!$J:$J,"Resolved") -> 4 | D6: =IFERROR(SUMPRODUCT((Working_Data!$K:$K>=A6)*(Working_Data!$K:$K<(A6+1))*(Working_Data!$J:$J="Resolved")*(Working_Data!$O:$O<=Working_Data!$I:$I))/C6,0) -> 0.75 | E6: =COUNTIFS(Working_Data!$J:$J,"Open")+COUNTIFS(Working_Data!$J:$J,"In Progress") -> 627
A7: 46028 | B7: =COUNTIFS(Working_Data!$B:$B,">="&A7,Working_Data!$B:$B,"<"&(A7+1)) -> 7 | C7: =COUNTIFS(Working_Data!$K:$K,">="&A7,Working_Data!$K:$K,"<"&(A7+1),Working_Data!$J:$J,"Resolved") -> 6 | D7: =IFERROR(SUMPRODUCT((Working_Data!$K:$K>=A7)*(Working_Data!$K:$K<(A7+1))*(Working_Data!$J:$J="Resolved")*(Working_Data!$O:$O<=Working_Data!$I:$I))/C7,0) -> 0.83333333 | E7: =COUNTIFS(Working_Data!$J:$J,"Open")+COUNTIFS(Working_Data!$J:$J,"In Progress") -> 627
A8: 46029 | B8: =COUNTIFS(Working_Data!$B:$B,">="&A8,Working_Data!$B:$B,"<"&(A8+1)) -> 16 | C8: =COUNTIFS(Working_Data!$K:$K,">="&A8,Working_Data!$K:$K,"<"&(A8+1),Working_Data!$J:$J,"Resolved") -> 6 | D8: =IFERROR(SUMPRODUCT((Working_Data!$K:$K>=A8)*(Working_Data!$K:$K<(A8+1))*(Working_Data!$J:$J="Resolved")*(Working_Data!$O:$O<=Working_Data!$I:$I))/C8,0) -> 0.66666667 | E8: =COUNTIFS(Working_Data!$J:$J,"Open")+COUNTIFS(Working_Data!$J:$J,"In Progress") -> 627
A9: 46030 | B9: =COUNTIFS(Working_Data!$B:$B,">="&A9,Working_Data!$B:$B,"<"&(A9+1)) -> 18 | C9: =COUNTIFS(Working_Data!$K:$K,">="&A9,Working_Data!$K:$K,"<"&(A9+1),Working_Data!$J:$J,"Resolved") -> 7 | D9: =IFERROR(SUMPRODUCT((Working_Data!$K:$K>=A9)*(Working_Data!$K:$K<(A9+1))*(Working_Data!$J:$J="Resolved")*(Working_Data!$O:$O<=Working_Data!$I:$I))/C9,0) -> 0.85714286 | E9: =COUNTIFS(Working_Data!$J:$J,"Open")+COUNTIFS(Working_Data!$J:$J,"In Progress") -> 627
A10: 46031 | B10: =COUNTIFS(Working_Data!$B:$B,">="&A10,Working_Data!$B:$B,"<"&(A10+1)) -> 14 | C10: =COUNTIFS(Working_Data!$K:$K,">="&A10,Working_Data!$K:$K,"<"&(A10+1),Working_Data!$J:$J,"Resolved") -> 5 | D10: =IFERROR(SUMPRODUCT((Working_Data!$K:$K>=A10)*(Working_Data!$K:$K<(A10+1))*(Working_Data!$J:$J="Resolved")*(Working_Data!$O:$O<=Working_Data!$I:$I))/C10,0) -> 1 | E10: =COUNTIFS(Working_Data!$J:$J,"Open")+COUNTIFS(Working_Data!$J:$J,"In Progress") -> 627
A11: 46032 | B11: =COUNTIFS(Working_Data!$B:$B,">="&A11,Working_Data!$B:$B,"<"&(A11+1)) -> 10 | C11: =COUNTIFS(Working_Data!$K:$K,">="&A11,Working_Data!$K:$K,"<"&(A11+1),Working_Data!$J:$J,"Resolved") -> 3 | D11: =IFERROR(SUMPRODUCT((Working_Data!$K:$K>=A11)*(Working_Data!$K:$K<(A11+1))*(Working_Data!$J:$J="Resolved")*(Working_Data!$O:$O<=Working_Data!$I:$I))/C11,0) -> 1 | E11: =COUNTIFS(Working_Data!$J:$J,"Open")+COUNTIFS(Working_Data!$J:$J,"In Progress") -> 627
A12: 46033 | B12: =COUNTIFS(Working_Data!$B:$B,">="&A12,Working_Data!$B:$B,"<"&(A12+1)) -> 14 | C12: =COUNTIFS(Working_Data!$K:$K,">="&A12,Working_Data!$K:$K,"<"&(A12+1),Working_Data!$J:$J,"Resolved") -> 2 | D12: =IFERROR(SUMPRODUCT((Working_Data!$K:$K>=A12)*(Working_Data!$K:$K<(A12+1))*(Working_Data!$J:$J="Resolved")*(Working_Data!$O:$O<=Working_Data!$I:$I))/C12,0) -> 1 | E12: =COUNTIFS(Working_Data!$J:$J,"Open")+COUNTIFS(Working_Data!$J:$J,"In Progress") -> 627
A13: 46034 | B13: =COUNTIFS(Working_Data!$B:$B,">="&A13,Working_Data!$B:$B,"<"&(A13+1)) -> 13 | C13: =COUNTIFS(Working_Data!$K:$K,">="&A13,Working_Data!$K:$K,"<"&(A13+1),Working_Data!$J:$J,"Resolved") -> 4 | D13: =IFERROR(SUMPRODUCT((Working_Data!$K:$K>=A13)*(Working_Data!$K:$K<(A13+1))*(Working_Data!$J:$J="Resolved")*(Working_Data!$O:$O<=Working_Data!$I:$I))/C13,0) -> 1 | E13: =COUNTIFS(Working_Data!$J:$J,"Open")+COUNTIFS(Working_Data!$J:$J,"In Progress") -> 627
... A243: 46264 | B243: =COUNTIFS(Working_Data!$B:$B,">="&A243,Working_Data!$B:$B,"<"&(A243+1)) -> 17 | C243: =COUNTIFS(Working_Data!$K:$K,">="&A243,Working_Data!$K:$K,"<"&(A243+1),Working_Data!$J:$J,"Resolved") -> 8 | D243: =IFERROR(SUMPRODUCT((Working_Data!$K:$K>=A243)*(Working_Data!$K:$K<(A243+1))*(Working_Data!$J:$J="Resolved")*(Working_Data!$O:$O<=Working_Data!$I:$I))/C243,0) -> 0.625 | E243: =COUNTIFS(Working_Data!$J:$J,"Open")+COUNTIFS(Working_Data!$J:$J,"In Progress") -> 627

Sheet Metrics
A1: Metrics
A2: Total Tickets | B2: =COUNTA(Working_Data!A:A)-1 -> 3200
A3: SLA Compliance Rate | B3: =SUMPRODUCT((Working_Data!J2:J3200="Resolved")*(Working_Data!O2:O3200<=Working_Data!I2:I3200))/COUNTIF(Working_Data!J2:J3200,"Resolved") -> 0.73547881
A4: Escalation Rate | B4: =COUNTIF(Working_Data!L:L,"Yes")/B2 -> 0.17875
A5: Average Resolution Time (Hours) | B5: =AVERAGEIF(Working_Data!J:J,"Resolved",Working_Data!O:O) -> 20.571615
A6: Backlog (Open + In Progress) | B6: =COUNTIF(Working_Data!J:J,"Open")+COUNTIF(Working_Data!J:J,"In Progress") -> 627
A7: Average CSAT Score | B7: =AVERAGE(Working_Data!M:M) -> 3.5622189
A8: Reopen Rate | B8: =COUNTIF(Working_Data!J:J,"Re-Opened")/B2 -> 0.0496875

Sheet KPI_Summary
A1: Metrics | B1: Yesterday (Aug 14) | C1: This Week (Aug 10-16) | D1: Month-to-Date (Aug 1-15)
A2: Tickets Opened | B2: =COUNTIFS(Working_Data!B:B,">="&DATE(2026,8,14),Working_Data!B:B,"<"&DATE(2026,8,15)) -> 12 | C2: =COUNTIFS(Working_Data!B:B,">="&DATE(2026,8,10),Working_Data!B:B,"<"&DATE(2026,8,17)) -> 90 | D2: =COUNTIFS(Working_Data!B:B,">="&DATE(2026,8,1),Working_Data!B:B,"<"&DATE(2026,8,16)) -> 192
A3: SLA Compliance Rate | B3: =SUMPRODUCT((Working_Data!J:J="Resolved")*(Working_Data!B:B>=DATE(2026,8,14))*(Working_Data!B:B<DATE(2026,8,15))*(Working_Data!O:O<=Working_Data!I:I))/SUMPRODUCT((Working_Data!J:J="Resolved")*(Working_Data!B:B>=DATE(2026,8,14))*(Working_Data!B:B<DATE(2026,8,15))) -> 0.55555556 | C3: =SUMPRODUCT((Working_Data!J:J="Resolved")*(Working_Data!B:B>=DATE(2026,8,10))*(Working_Data!B:B<DATE(2026,8,17))*(Working_Data!O:O<=Working_Data!I:I))/SUMPRODUCT((Working_Data!J:J="Resolved")*(Working_Data!B:B>=DATE(2026,8,10))*(Working_Data!B:B<DATE(2026,8,17))) -> 0.72727273 | D3: =SUMPRODUCT((Working_Data!J:J="Resolved")*(Working_Data!B:B>=DATE(2026,8,1))*(Working_Data!B:B<DATE(2026,8,16))*(Working_Data!O:O<=Working_Data!I:I))/SUMPRODUCT((Working_Data!J:J="Resolved")*(Working_Data!B:B>=DATE(2026,8,1))*(Working_Data!B:B<DATE(2026,8,16))) -> 0.75
A4: Avg Resolution Time (Hours) | B4: =AVERAGEIFS(Working_Data!O:O,Working_Data!J:J,"Resolved",Working_Data!B:B,">="&DATE(2026,8,14),Working_Data!B:B,"<"&DATE(2026,8,15)) -> 39.172222 | C4: =AVERAGEIFS(Working_Data!O:O,Working_Data!J:J,"Resolved",Working_Data!B:B,">="&DATE(2026,8,10),Working_Data!B:B,"<"&DATE(2026,8,17)) -> 26.25625 | D4: =AVERAGEIFS(Working_Data!O:O,Working_Data!J:J,"Resolved",Working_Data!B:B,">="&DATE(2026,8,1),Working_Data!B:B,"<"&DATE(2026,8,16)) -> 24.536325
